<?xml version="1.0" encoding="utf-8"?>
<!-- This URDF was automatically created by SolidWorks to URDF Exporter! Originally created by Stephen Brawner (brawner@gmail.com) 
     Commit Version: 1.6.0-4-g7f85cfe  Build Version: 1.6.7995.38578
     For more information, please see http://wiki.ros.org/sw_urdf_exporter -->
<robot
  name="Danaus12_Pendulum">
  <link
    name="base_link">
    <inertial>
      <origin
        xyz="0.0034397 -5.0413E-06 -0.017794"
        rpy="0 0 0" />
      <mass
        value="0.2397" />
      <inertia
        ixx="0.00048818"
        ixy="-3.9864E-09"
        ixz="2.2115E-09"
        iyy="0.00048184"
        iyz="6.0292E-11"
        izz="0.0009523" />
    </inertial>
    <visual>
      <origin
        xyz="0 0 0"
        rpy="0 0 0" />
      <geometry>
        <mesh
          filename="package://Danaus12_Pendulum/meshes/base_link.STL" />
      </geometry>
      <material
        name="">
        <color
          rgba="0.75294 0.75294 0.75294 1" />
      </material>
    </visual>
    <collision>
      <origin
        xyz="0 0 0"
        rpy="0 0 0" />
      <geometry>
        <mesh
          filename="package://Danaus12_Pendulum/meshes/base_link.STL" />
      </geometry>
    </collision>
  </link>
  <link
    name="rotor_0">
    <inertial>
      <origin
        xyz="2.2563E-07 -3.2291E-06 -0.0018272"
        rpy="0 0 0" />
      <mass
        value="0.0032761" />
      <inertia
        ixx="1.0527E-06"
        ixy="-2.4429E-10"
        ixz="-1.7374E-11"
        iyy="1.0527E-06"
        iyz="1.5733E-11"
        izz="2.0815E-06" />
    </inertial>
    <visual>
      <origin
        xyz="0 0 0"
        rpy="0 0 0" />
      <geometry>
        <mesh
          filename="package://Danaus12_Pendulum/meshes/rotor_0.STL" />
      </geometry>
      <material
        name="">
        <color
          rgba="0.79216 0.81961 0.93333 1" />
      </material>
    </visual>
    <collision>
      <origin
        xyz="0 0 0"
        rpy="0 0 0" />
      <geometry>
        <mesh
          filename="package://Danaus12_Pendulum/meshes/rotor_0.STL" />
      </geometry>
    </collision>
  </link>
  <joint
    name="rotor_0_cont"
    type="continuous">
    <origin
      xyz="0.063592 -0.088805 0.0035193"
      rpy="0 0 0" />
    <parent
      link="base_link" />
    <child
      link="rotor_0" />
    <axis
      xyz="0 0 1" />
  </joint>
  <link
    name="rotor_1">
    <inertial>
      <origin
        xyz="3.0281E-06 3.4514E-06 -0.0018273"
        rpy="0 0 0" />
      <mass
        value="0.0032761" />
      <inertia
        ixx="1.053E-06"
        ixy="1.0257E-10"
        ixz="-1.0673E-11"
        iyy="1.0527E-06"
        iyz="-8.4164E-12"
        izz="2.0817E-06" />
    </inertial>
    <visual>
      <origin
        xyz="0 0 0"
        rpy="0 0 0" />
      <geometry>
        <mesh
          filename="package://Danaus12_Pendulum/meshes/rotor_1.STL" />
      </geometry>
      <material
        name="">
        <color
          rgba="0.79216 0.81961 0.93333 1" />
      </material>
    </visual>
    <collision>
      <origin
        xyz="0 0 0"
        rpy="0 0 0" />
      <geometry>
        <mesh
          filename="package://Danaus12_Pendulum/meshes/rotor_1.STL" />
      </geometry>
    </collision>
  </link>
  <joint
    name="rotor_1_cont"
    type="continuous">
    <origin
      xyz="-0.071008 0.088795 0.0035193"
      rpy="0 0 0" />
    <parent
      link="base_link" />
    <child
      link="rotor_1" />
    <axis
      xyz="0 0 1" />
  </joint>
  <link
    name="rotor_2">
    <inertial>
      <origin
        xyz="6.9532E-06 7.1226E-06 -0.0018255"
        rpy="0 0 0" />
      <mass
        value="0.0032742" />
      <inertia
        ixx="1.0522E-06"
        ixy="2.8174E-10"
        ixz="5.4977E-11"
        iyy="1.052E-06"
        iyz="2.4597E-11"
        izz="2.0804E-06" />
    </inertial>
    <visual>
      <origin
        xyz="0 0 0"
        rpy="0 0 0" />
      <geometry>
        <mesh
          filename="package://Danaus12_Pendulum/meshes/rotor_2.STL" />
      </geometry>
      <material
        name="">
        <color
          rgba="0.50196 1 0.50196 1" />
      </material>
    </visual>
    <collision>
      <origin
        xyz="0 0 0"
        rpy="0 0 0" />
      <geometry>
        <mesh
          filename="package://Danaus12_Pendulum/meshes/rotor_2.STL" />
      </geometry>
    </collision>
  </link>
  <joint
    name="rotor_2_cont"
    type="continuous">
    <origin
      xyz="0.063592 0.088795 0.0035193"
      rpy="0 0 0" />
    <parent
      link="base_link" />
    <child
      link="rotor_2" />
    <axis
      xyz="0 0 1" />
  </joint>
  <link
    name="rotor_3">
    <inertial>
      <origin
        xyz="-6.7862E-06 4.9333E-06 -0.0018251"
        rpy="0 0 0" />
      <mass
        value="0.0032734" />
      <inertia
        ixx="1.0517E-06"
        ixy="-5.171E-11"
        ixz="-3.874E-11"
        iyy="1.0522E-06"
        iyz="4.5399E-11"
        izz="2.0801E-06" />
    </inertial>
    <visual>
      <origin
        xyz="0 0 0"
        rpy="0 0 0" />
      <geometry>
        <mesh
          filename="package://Danaus12_Pendulum/meshes/rotor_3.STL" />
      </geometry>
      <material
        name="">
        <color
          rgba="0.50196 1 0.50196 1" />
      </material>
    </visual>
    <collision>
      <origin
        xyz="0 0 0"
        rpy="0 0 0" />
      <geometry>
        <mesh
          filename="package://Danaus12_Pendulum/meshes/rotor_3.STL" />
      </geometry>
    </collision>
  </link>
  <joint
    name="rotor_3_cont"
    type="continuous">
    <origin
      xyz="-0.071008 -0.088805 0.0035193"
      rpy="0 0 0" />
    <parent
      link="base_link" />
    <child
      link="rotor_3" />
    <axis
      xyz="0 0 1" />
  </joint>
  <link
    name="penulum">
    <inertial>
      <origin
        xyz="-0.0019948 0.0001352 0.53166"
        rpy="0 0 0" />
      <mass
        value="0.020218" />
      <inertia
        ixx="0.0016849"
        ixy="-4.832E-39"
        ixz="-2.0614E-19"
        iyy="0.0016849"
        iyz="0"
        izz="2.6886E-07" />
    </inertial>
    <visual>
      <origin
        xyz="0 0 0"
        rpy="0 0 0" />
      <geometry>
        <mesh
          filename="package://Danaus12_Pendulum/meshes/penulum.STL" />
      </geometry>
      <material
        name="">
        <color
          rgba="0.75294 0.75294 0.75294 1" />
      </material>
    </visual>
    <collision>
      <origin
        xyz="0 0 0"
        rpy="0 0 0" />
      <geometry>
        <mesh
          filename="package://Danaus12_Pendulum/meshes/penulum.STL" />
      </geometry>
    </collision>
  </link>
  <joint
    name="pendulum_cont"
    type="fixed">
    <origin
      xyz="0 0 0"
      rpy="0 0 0" />
    <parent
      link="base_link" />
    <child
      link="penulum" />
    <axis
      xyz="0 0 0" />
  </joint>
</robot>